[2024-09-25 15:22:25,371] INFO _log() L97   [31m[1mWARNING: This is a development server. Do not use it in a production deployment. Use a production WSGI server instead.[0m
 * Running on all addresses (0.0.0.0)
 * Running on http://127.0.0.1:5000
 * Running on http://192.168.1.69:5000 - call_trace=C:\Projetos\API-Flash\env\Lib\site-packages\werkzeug\_internal.py L97  
[2024-09-25 15:22:25,373] INFO _log() L97   [33mPress CTRL+C to quit[0m - call_trace=C:\Projetos\API-Flash\env\Lib\site-packages\werkzeug\_internal.py L97  
[2024-09-25 15:22:25,374] INFO _log() L97    * Restarting with stat - call_trace=C:\Projetos\API-Flash\env\Lib\site-packages\werkzeug\_internal.py L97  
[2024-09-25 15:22:44,585] ERROR log_exception() L838  Exception on /produto [POST] - call_trace=C:\Projetos\API-Flash\env\Lib\site-packages\flask\app.py L838 
Traceback (most recent call last):
  File "C:\Projetos\API-Flash\env\Lib\site-packages\flask\app.py", line 1473, in wsgi_app
    response = self.full_dispatch_request()
               ^^^^^^^^^^^^^^^^^^^^^^^^^^^^
  File "C:\Projetos\API-Flash\env\Lib\site-packages\flask\app.py", line 882, in full_dispatch_request
    rv = self.handle_user_exception(e)
         ^^^^^^^^^^^^^^^^^^^^^^^^^^^^^
  File "C:\Projetos\API-Flash\env\Lib\site-packages\flask_cors\extension.py", line 194, in wrapped_function
    return cors_after_request(app.make_response(f(*args, **kwargs)))
                                                ^^^^^^^^^^^^^^^^^^
  File "C:\Projetos\API-Flash\env\Lib\site-packages\flask\app.py", line 880, in full_dispatch_request
    rv = self.dispatch_request()
         ^^^^^^^^^^^^^^^^^^^^^^^
  File "C:\Projetos\API-Flash\env\Lib\site-packages\flask\app.py", line 865, in dispatch_request
    return self.ensure_sync(self.view_functions[rule.endpoint])(**view_args)  # type: ignore[no-any-return]
           ^^^^^^^^^^^^^^^^^^^^^^^^^^^^^^^^^^^^^^^^^^^^^^^^^^^^^^^^^^^^^^^^^
  File "C:\Projetos\API-Flash\env\Lib\site-packages\flask_openapi3\scaffold.py", line 117, in view_func
    response = func(**func_kwargs)
               ^^^^^^^^^^^^^^^^^^^
  File "C:\Projetos\API-Flash\app.py", line 42, in add_produto
    produto = Produto(
              ^^^^^^^^
  File "<string>", line 4, in __init__
  File "C:\Projetos\API-Flash\env\Lib\site-packages\sqlalchemy\orm\state.py", line 566, in _initialize_instance
    manager.dispatch.init(self, args, kwargs)
  File "C:\Projetos\API-Flash\env\Lib\site-packages\sqlalchemy\event\attr.py", line 497, in __call__
    fn(*args, **kw)
  File "C:\Projetos\API-Flash\env\Lib\site-packages\sqlalchemy\orm\mapper.py", line 4396, in _event_on_init
    instrumenting_mapper._check_configure()
  File "C:\Projetos\API-Flash\env\Lib\site-packages\sqlalchemy\orm\mapper.py", line 2388, in _check_configure
    _configure_registries({self.registry}, cascade=True)
  File "C:\Projetos\API-Flash\env\Lib\site-packages\sqlalchemy\orm\mapper.py", line 4204, in _configure_registries
    _do_configure_registries(registries, cascade)
  File "C:\Projetos\API-Flash\env\Lib\site-packages\sqlalchemy\orm\mapper.py", line 4245, in _do_configure_registries
    mapper._post_configure_properties()
  File "C:\Projetos\API-Flash\env\Lib\site-packages\sqlalchemy\orm\mapper.py", line 2405, in _post_configure_properties
    prop.init()
  File "C:\Projetos\API-Flash\env\Lib\site-packages\sqlalchemy\orm\interfaces.py", line 584, in init
    self.do_init()
  File "C:\Projetos\API-Flash\env\Lib\site-packages\sqlalchemy\orm\relationships.py", line 1647, in do_init
    self._generate_backref()
  File "C:\Projetos\API-Flash\env\Lib\site-packages\sqlalchemy\orm\relationships.py", line 2075, in _generate_backref
    raise sa_exc.ArgumentError(
sqlalchemy.exc.ArgumentError: Error creating backref 'pedidos' on relationship 'Pedido.cliente': property of that name exists on mapper 'Mapper[Cliente(cliente)]'
[2024-09-25 15:22:44,592] INFO _log() L97   127.0.0.1 - - [25/Sep/2024 15:22:44] "[35m[1mPOST /produto HTTP/1.1[0m" 500 - - call_trace=C:\Projetos\API-Flash\env\Lib\site-packages\werkzeug\_internal.py L97  
[2024-09-25 15:22:55,526] ERROR log_exception() L838  Exception on /produto [GET] - call_trace=C:\Projetos\API-Flash\env\Lib\site-packages\flask\app.py L838 
Traceback (most recent call last):
  File "C:\Projetos\API-Flash\env\Lib\site-packages\flask\app.py", line 1473, in wsgi_app
    response = self.full_dispatch_request()
               ^^^^^^^^^^^^^^^^^^^^^^^^^^^^
  File "C:\Projetos\API-Flash\env\Lib\site-packages\flask\app.py", line 882, in full_dispatch_request
    rv = self.handle_user_exception(e)
         ^^^^^^^^^^^^^^^^^^^^^^^^^^^^^
  File "C:\Projetos\API-Flash\env\Lib\site-packages\flask_cors\extension.py", line 194, in wrapped_function
    return cors_after_request(app.make_response(f(*args, **kwargs)))
                                                ^^^^^^^^^^^^^^^^^^
  File "C:\Projetos\API-Flash\env\Lib\site-packages\flask\app.py", line 880, in full_dispatch_request
    rv = self.dispatch_request()
         ^^^^^^^^^^^^^^^^^^^^^^^
  File "C:\Projetos\API-Flash\env\Lib\site-packages\flask\app.py", line 865, in dispatch_request
    return self.ensure_sync(self.view_functions[rule.endpoint])(**view_args)  # type: ignore[no-any-return]
           ^^^^^^^^^^^^^^^^^^^^^^^^^^^^^^^^^^^^^^^^^^^^^^^^^^^^^^^^^^^^^^^^^
  File "C:\Projetos\API-Flash\env\Lib\site-packages\flask_openapi3\scaffold.py", line 117, in view_func
    response = func(**func_kwargs)
               ^^^^^^^^^^^^^^^^^^^
  File "C:\Projetos\API-Flash\app.py", line 77, in get_produto
    produto = session.query(Produto).filter(Produto.id == produto_id).first()
              ^^^^^^^^^^^^^^^^^^^^^^
  File "C:\Projetos\API-Flash\env\Lib\site-packages\sqlalchemy\orm\session.py", line 2952, in query
    return self._query_cls(entities, self, **kwargs)
           ^^^^^^^^^^^^^^^^^^^^^^^^^^^^^^^^^^^^^^^^^
  File "C:\Projetos\API-Flash\env\Lib\site-packages\sqlalchemy\orm\query.py", line 275, in __init__
    self._set_entities(entities)
  File "C:\Projetos\API-Flash\env\Lib\site-packages\sqlalchemy\orm\query.py", line 288, in _set_entities
    coercions.expect(
  File "C:\Projetos\API-Flash\env\Lib\site-packages\sqlalchemy\sql\coercions.py", line 389, in expect
    insp._post_inspect
  File "C:\Projetos\API-Flash\env\Lib\site-packages\sqlalchemy\util\langhelpers.py", line 1253, in __get__
    obj.__dict__[self.__name__] = result = self.fget(obj)
                                           ^^^^^^^^^^^^^^
  File "C:\Projetos\API-Flash\env\Lib\site-packages\sqlalchemy\orm\mapper.py", line 2711, in _post_inspect
    self._check_configure()
  File "C:\Projetos\API-Flash\env\Lib\site-packages\sqlalchemy\orm\mapper.py", line 2388, in _check_configure
    _configure_registries({self.registry}, cascade=True)
  File "C:\Projetos\API-Flash\env\Lib\site-packages\sqlalchemy\orm\mapper.py", line 4204, in _configure_registries
    _do_configure_registries(registries, cascade)
  File "C:\Projetos\API-Flash\env\Lib\site-packages\sqlalchemy\orm\mapper.py", line 4241, in _do_configure_registries
    raise e
sqlalchemy.exc.InvalidRequestError: One or more mappers failed to initialize - can't proceed with initialization of other mappers. Triggering mapper: 'Mapper[Pedido(pedido)]'. Original exception was: Error creating backref 'pedidos' on relationship 'Pedido.cliente': property of that name exists on mapper 'Mapper[Cliente(cliente)]'
[2024-09-25 15:22:55,532] INFO _log() L97   127.0.0.1 - - [25/Sep/2024 15:22:55] "[35m[1mGET /produto?id=1&nome=Bolo%20de%20Laranja HTTP/1.1[0m" 500 - - call_trace=C:\Projetos\API-Flash\env\Lib\site-packages\werkzeug\_internal.py L97  
